Workbook

Sheet Raw Data
A1: Metric | B1: Q1-2022 | C1: Q2-2022 | D1: Q3-2022 | E1: Q4-2022 | F1: Q1-2023 | G1: Q2-2023 | H1: Q3-2023 | I1: Q4-2023 | J1: Q1-2024 | K1: Q2-2024 | L1: Q3-2024 | M1: Q4-2024
A2: Net Revenue($M) | B2: 12933 | C2: 11860 | D2: 11980 | E2: 10590 | F2: 12220 | G2: 10900 | H2: 11820 | I2: 11320 | J2: 14210 | K2: 12730 | L2: 12700 | M2: 13870
A3: FICC($M) | B3: 4720 | C3: 3610 | D3: 3530 | E3: 2690 | F3: 3930 | G3: 2710 | H3: 3380 | I3: 2030 | J3: 4320 | K3: 3180 | L3: 2960 | M3: 2740
A4: FICC Net Revenue ($M) | B4: =B2-B3 -> 8213 | C4: =C2-C3 -> 8250 | D4: =D2-D3 -> 8450 | E4: =E2-E3 -> 7900 | F4: =F2-F3 -> 8290 | G4: =G2-G3 -> 8190 | H4: =H2-H3 -> 8440 | I4: =I2-I3 -> 9290 | ... M4: =M2-M3 -> 11130
A5: Equities ($M) | B5: 3150 | C5: 2860 | D5: 2680 | E5: 2070 | F5: 3020 | G5: 2970 | H5: 2960 | I5: 2610 | J5: 3310 | K5: 3170 | L5: 3500 | M5: 3450
A6: Equities Net Revenue ($M) | B6: =B2-B5 -> 9783 | C6: =C2-C5 -> 9000 | D6: =D2-D5 -> 9300 | E6: =E2-E5 -> 8520 | F6: =F2-F5 -> 9200 | G6: =G2-G5 -> 7930 | H6: =H2-H5 -> 8860 | I6: =I2-I5 -> 8710 | ... M6: =M2-M5 -> 10420
A7: Total Markets Revenue($M) | B7: =B3+B5 -> 7870 | C7: =C3+C5 -> 6470 | D7: =D3+D5 -> 6210 | E7: =E3+E5 -> 4760 | F7: =F3+F5 -> 6950 | G7: =G3+G5 -> 5680 | H7: =H3+H5 -> 6340 | I7: =I3+I5 -> 4640 | ... M7: =M3+M5 -> 6190
A8: Comp & Benefits($M) | B8: =B10*0.485 -> 2143.7 | C8: =C10*0.485 -> 2126.24 | D8: =D10*0.485 -> 2140.305 | E8: =E10*0.485 -> 2247.975 | F8: =F10*0.475 -> 2087.625 | G8: =G10*0.475 -> 2122.775 | H8: =H10*0.475 -> 2249.6 | I8: =I10*0.475 -> 2109 | J8: =J10*0.472 -> 2419.472 | K8: =K10*0.472 -> 2384.072 | L8: =L10*0.472 -> 2323.184 | M8: =M10*0.472 -> 2308.08
A9: Non-Comp Expenses($M) | B9: =B10-B8 -> 2276.3 | C9: =C10-C8 -> 2257.76 | D9: =D10-D8 -> 2272.695 | E9: =E10-E8 -> 2387.025 | F9: =F10-F8 -> 2307.375 | G9: =G10-G8 -> 2346.225 | H9: =H10-H8 -> 2486.4 | I9: =I10-I8 -> 2331 | ... M9: =M10-M8 -> 2581.92
A10: Total Operating Expense($M) | B10: 4420 | C10: 4384 | D10: 4413 | E10: 4635 | F10: 4395 | G10: 4469 | H10: 4736 | I10: 4440 | J10: 5126 | K10: 5051 | L10: 4922 | M10: 4890
A11: Pre-Tax Earnings($M) | B11: 4656 | C11: 3544 | D11: 3756 | E11: 1530 | F11: 3993 | G11: 1736 | H11: 2756 | I11: 2254 | J11: 5237 | K11: 3916 | L11: 3987 | M11: 5257
A12: Pre-Tax Margin % | B12: =B11/B2 -> 0.36000928 | C12: =C11/C2 -> 0.29881956 | D12: =D11/D2 -> 0.31352254 | E12: =E11/E2 -> 0.14447592 | F12: =F11/F2 -> 0.32675941 | G12: =G11/G2 -> 0.15926606 | H12: =H11/H2 -> 0.23316413 | I12: =I11/I2 -> 0.19911661 | ... M12: =M11/M2 -> 0.37901947
A13: Firm Headcount | B13: 45100 | C13: 47000 | D13: 49100 | E13: 48500 | F13: 45400 | G13: 44600 | H13: 45900 | I13: 45300 | J13: 44400 | K13: 44300 | L13: 46400 | M13: 46500

Sheet P&L Model
A1: GOLDMAN SACHS — GLOBAL MARKETS P&L MODEL
A3: Market Revenue | B3: Q1-2022 | C3: Q2-2022 | D3: Q3-2022 | E3: Q4-2022 | F3: Q1-2023 | G3: Q2-2023 | H3: Q3-2023 | I3: Q4-2023 | J3: Q1-2024 | K3: Q2-2024 | L3: Q3-2024 | M3: Q4-2024
A4: FICC | B4: ='Raw Data'!B3 -> 4720 | C4: ='Raw Data'!C3 -> 3610 | D4: ='Raw Data'!D3 -> 3530 | E4: ='Raw Data'!E3 -> 2690 | F4: ='Raw Data'!F3 -> 3930 | G4: ='Raw Data'!G3 -> 2710 | H4: ='Raw Data'!H3 -> 3380 | I4: ='Raw Data'!I3 -> 2030 | ... M4: ='Raw Data'!M3 -> 2740
A5: Equities | B5: ='Raw Data'!B5 -> 3150 | C5: ='Raw Data'!C5 -> 2860 | D5: ='Raw Data'!D5 -> 2680 | E5: ='Raw Data'!E5 -> 2070 | F5: ='Raw Data'!F5 -> 3020 | G5: ='Raw Data'!G5 -> 2970 | H5: ='Raw Data'!H5 -> 2960 | I5: ='Raw Data'!I5 -> 2610 | ... M5: ='Raw Data'!M5 -> 3450
A6: Total Markets Revenue | B6: =B4+B5 -> 7870 | C6: =C4+C5 -> 6470 | D6: =D4+D5 -> 6210 | E6: =E4+E5 -> 4760 | F6: =F4+F5 -> 6950 | G6: =G4+G5 -> 5680 | H6: =H4+H5 -> 6340 | I6: =I4+I5 -> 4640 | ... M6: =M4+M5 -> 6190
A9: OPERATING EXPENSES | B9: Q1-2022 | C9: Q2-2022 | D9: Q3-2022 | E9: Q4-2022 | F9: Q1-2023 | G9: Q2-2023 | H9: Q3-2023 | I9: Q4-2023 | J9: Q1-2024 | K9: Q2-2024 | L9: Q3-2024 | M9: Q4-2024
A10: Compensation | B10: ='Raw Data'!B8 -> 2143.7 | C10: ='Raw Data'!C8 -> 2126.24 | D10: ='Raw Data'!D8 -> 2140.305 | E10: ='Raw Data'!E8 -> 2247.975 | F10: ='Raw Data'!F8 -> 2087.625 | G10: ='Raw Data'!G8 -> 2122.775 | H10: ='Raw Data'!H8 -> 2249.6 | I10: ='Raw Data'!I8 -> 2109 | ... M10: ='Raw Data'!M8 -> 2308.08
A11: Non-Compensation | B11: ='Raw Data'!B9 -> 2276.3 | C11: ='Raw Data'!C9 -> 2257.76 | D11: ='Raw Data'!D9 -> 2272.695 | E11: ='Raw Data'!E9 -> 2387.025 | F11: ='Raw Data'!F9 -> 2307.375 | G11: ='Raw Data'!G9 -> 2346.225 | H11: ='Raw Data'!H9 -> 2486.4 | I11: ='Raw Data'!I9 -> 2331 | ... M11: ='Raw Data'!M9 -> 2581.92
A12: Total Operating Expense | B12: =SUBTOTAL(109,Table5[Q1-2022]) -> 4420 | C12: =SUBTOTAL(109,Table5[Q2-2022]) -> 4384 | D12: =SUBTOTAL(109,Table5[Q3-2022]) -> 4413 | E12: =SUBTOTAL(109,Table5[Q4-2022]) -> 4635 | F12: =SUBTOTAL(109,Table5[Q1-2023]) -> 4395 | G12: =SUBTOTAL(109,Table5[Q2-2023]) -> 4469 | H12: =SUBTOTAL(109,Table5[Q3-2023]) -> 4736 | I12: =SUBTOTAL(109,Table5[Q4-2023]) -> 4440 | J12: =SUBTOTAL(109,Table5[Q1-2024]) -> 5126 | K12: =SUBTOTAL(109,Table5[Q2-2024]) -> 5051 | L12: =SUBTOTAL(109,Table5[Q3-2024]) -> 4922 | M12: =SUBTOTAL(109,Table5[Q4-2024]) -> 4890
XFD13: =SUBTOTAL(103,#REF!) -> #REF!
A15: KEY METRICS | B15: Q1-2022 | C15: Q2-2022 | D15: Q3-2022 | E15: Q4-2022 | F15: Q1-2023 | G15: Q2-2023 | H15: Q3-2023 | I15: Q4-2023 | J15: Q1-2024 | K15: Q2-2024 | L15: Q3-2024 | M15: Q4-2024
A16: Pre-Tax Margin % | B16: ='Raw Data'!B11/'Raw Data'!B2 -> 0.36000928 | C16: ='Raw Data'!C11/'Raw Data'!C2 -> 0.29881956 | D16: ='Raw Data'!D11/'Raw Data'!D2 -> 0.31352254 | E16: ='Raw Data'!E11/'Raw Data'!E2 -> 0.14447592 | F16: ='Raw Data'!F11/'Raw Data'!F2 -> 0.32675941 | G16: ='Raw Data'!G11/'Raw Data'!G2 -> 0.15926606 | H16: ='Raw Data'!H11/'Raw Data'!H2 -> 0.23316413 | I16: ='Raw Data'!I11/'Raw Data'!I2 -> 0.19911661 | ... M16: ='Raw Data'!M11/'Raw Data'!M2 -> 0.37901947
A17: Comp Ratio | B17: =B10/B6 -> 0.27238882 | C17: =C10/C6 -> 0.3286306 | D17: =D10/D6 -> 0.34465459 | E17: =E10/E6 -> 0.47226366 | F17: =F10/F6 -> 0.3003777 | G17: =G10/G6 -> 0.37372799 | H17: =H10/H6 -> 0.3548265 | I17: =I10/I6 -> 0.45452586 | ... M17: =M10/M6 -> 0.37287237
A18: Revenue per Head | B18: ='Raw Data'!B7/'Raw Data'!B13 -> 0.17450111 | C18: ='Raw Data'!C7/'Raw Data'!C13 -> 0.13765957 | D18: ='Raw Data'!D7/'Raw Data'!D13 -> 0.12647658 | E18: ='Raw Data'!E7/'Raw Data'!E13 -> 0.09814433 | F18: ='Raw Data'!F7/'Raw Data'!F13 -> 0.1530837 | G18: ='Raw Data'!G7/'Raw Data'!G13 -> 0.12735426 | H18: ='Raw Data'!H7/'Raw Data'!H13 -> 0.13812636 | I18: ='Raw Data'!I7/'Raw Data'!I13 -> 0.10242826 | ... M18: ='Raw Data'!M7/'Raw Data'!M13 -> 0.13311828
A19: FICC % of Revenue | B19: ='Raw Data'!B3/'Raw Data'!B2 -> 0.36495786 | C19: ='Raw Data'!C3/'Raw Data'!C2 -> 0.30438449 | D19: ='Raw Data'!D3/'Raw Data'!D2 -> 0.29465776 | E19: ='Raw Data'!E3/'Raw Data'!E2 -> 0.25401322 | F19: ='Raw Data'!F3/'Raw Data'!F2 -> 0.32160393 | G19: ='Raw Data'!G3/'Raw Data'!G2 -> 0.24862385 | H19: ='Raw Data'!H3/'Raw Data'!H2 -> 0.28595601 | I19: ='Raw Data'!I3/'Raw Data'!I2 -> 0.17932862 | ... M19: ='Raw Data'!M3/'Raw Data'!M2 -> 0.19754867
A20: Equities % of Revenue | B20: ='Raw Data'!B5/'Raw Data'!B2 -> 0.24356298 | C20: ='Raw Data'!C5/'Raw Data'!C2 -> 0.24114671 | D20: ='Raw Data'!D5/'Raw Data'!D2 -> 0.22370618 | E20: ='Raw Data'!E5/'Raw Data'!E2 -> 0.19546742 | F20: ='Raw Data'!F5/'Raw Data'!F2 -> 0.24713584 | G20: ='Raw Data'!G5/'Raw Data'!G2 -> 0.27247706 | H20: ='Raw Data'!H5/'Raw Data'!H2 -> 0.25042301 | I20: ='Raw Data'!I5/'Raw Data'!I2 -> 0.23056537 | ... M20: ='Raw Data'!M5/'Raw Data'!M2 -> 0.24873828
B23: FULL YEAR SUMMARY
B24: FY2022 | C24: FY2023 | D24: FY2024
A25: Net Revenue | B25: =SUM('Raw Data'!B2:E2) -> 47363 | C25: =SUM('Raw Data'!F2:I2) -> 46260 | D25: =SUM('Raw Data'!J2:M2) -> 53510
A26: Total Markets Revenue | B26: =SUM('Raw Data'!B7:E7) -> 25310 | C26: =SUM('Raw Data'!F7:I7) -> 23610 | D26: =SUM('Raw Data'!J7:M7) -> 26630
A27: Total OpEx | B27: =SUM('Raw Data'!B10:E10) -> 17852 | C27: =SUM('Raw Data'!F10:I10) -> 18040 | D27: =SUM('Raw Data'!J10:M10) -> 19989
A28: Pre-Tax Earnings | B28: =SUM('Raw Data'!B11:E11) -> 13486 | C28: =SUM('Raw Data'!F11:I11) -> 10739 | D28: =SUM('Raw Data'!J11:M11) -> 18397
A29: Pre-Tax Margin | B29: =B28/B25 -> 0.28473703 | C29: =C28/C25 -> 0.2321444 | D29: =D28/D25 -> 0.3438049

Sheet Variance Analysis
B2: Revenue Variance Table
A4: Metrics | B4: Q1-2024 | C4: Q1-2023 | D4: variance($) | E4: variance(%)
A5: FICC | B5: ='Raw Data'!J3 -> 4320 | C5: ='Raw Data'!F3 -> 3930 | D5: =B5-C5 -> 390 | E5: =(B5-C5)/B5 -> 0.090277778
A6: Equities | B6: ='Raw Data'!J5 -> 3310 | C6: ='Raw Data'!F5 -> 3020 | D6: =B6-C6 -> 290 | E6: =(B6-C6)/B6 -> 0.087613293
A7: Total Market Revenue | B7: ='P&L Model'!J6 -> 7630 | C7: ='P&L Model'!F6 -> 6950 | D7: =B7-C7 -> 680 | E7: =(B7-C7)/B7 -> 0.089121887
A8: Operating Expense | B8: ='Raw Data'!J10 -> 5126 | C8: ='Raw Data'!F10 -> 4395 | D8: =B8-C8 -> 731 | E8: =(B8-C8)/B8 -> 0.14260632
A9: comp | B9: ='Raw Data'!J8 -> 2419.472 | C9: ='Raw Data'!F8 -> 2087.625 | D9: =B9-C9 -> 331.847 | E9: =(B9-C9)/B9 -> 0.13715678
A10: non-comp | B10: ='Raw Data'!J9 -> 2706.528 | C10: ='Raw Data'!F9 -> 2307.375 | D10: =B10-C10 -> 399.153 | E10: =(B10-C10)/B10 -> 0.14747788
A11: Pre-Tax Income | B11: 5237 | C11: 3993 | D11: =B11-C11 -> 1244 | E11: =(B11-C11)/B11 -> 0.23754058
A12: Pre-Tax Margin % | B12: 0.37 | C12: 0.33 | D12: =B12-C12 -> 0.04 | E12: =(B12-C12)/B12 -> 0.10810811
A13: Headcount | B13: 44400 | C13: 45400 | D13: =B13-C13 -> -1000 | E13: =(B13-C13)/B13 -> -0.022522523
A14: Revenue /Head | B14: ='Raw Data'!B2/'Raw Data'!B8 -> 6.033027 | C14: ='Raw Data'!C2/'Raw Data'!C8 -> 5.5779216 | D14: =B14-C14 -> 0.45510542 | E14: =(B14-C14)/B14 -> 0.075435668
A15: Comp ratio | B15: =B9/B7 -> 0.31709987 | C15: =C9/C7 -> 0.3003777 | D15: =B15-C15 -> 0.016722171 | E15: =(B15-C15)/B15 -> 0.052734715
D18: FINDINGS
B20: Global Markets revenues rose $680M (+9% YoY) in Q1 2024, driven by stronger FICC performance on elevated rates volatility and increased client hedging activity, with Equities contributing $290M and FICC contributing $390M of incremental revenue.

Sheet Assumptions Page 1
B1: HISTORICAL MACRO DATA
C3: Q1-2023 | D3: Q2-2023 | E3: Q3-2023 | F3: Q4-2023 | G3: Q1-2024 | H3: Q2-2024 | I3: Q3-2024 | J3: Q4-2024 | M3: 8-Quarter Average | N3: 8-Quarter High | O3: 8-Quarter Low
B4: VIX Quarterly Avg | C4: 19.6 | D4: 15.77 | E4: 14.91 | F4: 14.5 | G4: 13.59 | H4: 13.67 | I4: 16.03 | J4: 18.01 | L4: VIX Quarterly Avg | M4: =AVERAGE(C4:J4) -> 15.76 | N4: =MAX(C4:J4) -> 19.6 | O4: =MIN(C4:J4) -> 13.59
B5: S&P 500 Return | C5: 0.008 | D5: 0.0674 | E5: 0.0656 | F5: 0.1373 | G5: 0.0844 | H5: 0.0844 | I5: 0.0435 | J5: 0.0309 | L5: S&P 500 Return | M5: =AVERAGE(C5:J5) -> 0.0651875 | N5: =MAX(C5:J5) -> 0.1373 | O5: =MIN(C5:J5) -> 0.008
B6: Fed Funds Rate | C6: 0.0481 | D6: 0.0531 | E6: 0.0531 | F6: 0.0531 | G6: 0.0531 | H6: 0.0531 | I6: 0.0481 | J6: 0.0433 | L6: Fed Funds Rate | M6: =AVERAGE(C6:J6) -> 0.050625 | N6: =MAX(C6:J6) -> 0.0531 | O6: =MIN(C6:J6) -> 0.0433
B7: 10Y Treasury Yield | C7: 0.0348 | D7: 0.0381 | E7: 0.0459 | F7: 0.0388 | G7: 0.042 | H7: 0.0436 | I7: 0.0381 | J7: 0.0458 | L7: 10Y Treasury Yield | M7: =AVERAGE(C7:J7) -> 0.0408875 | N7: =MAX(C7:J7) -> 0.0459 | O7: =MIN(C7:J7) -> 0.0348
B8: Credit Spreads(bps) | C8: 149 | D8: 129 | E8: 125 | F8: 104 | G8: 94 | H8: 96 | I8: 92 | J8: 82 | L8: Credit Spreads(bps) | M8: =AVERAGE(C8:J8) -> 108.875 | N8: =MAX(C8:J8) -> 149 | O8: =MIN(C8:J8) -> 82
B11: HISTORICAL BUSINESS METRICS
C13: Q1-2023 | D13: Q2-2023 | E13: Q3-2023 | F13: Q4-2023 | G13: Q1-2024 | H13: Q2-2024 | I13: Q3-2024 | J13: Q4-2024
B14: FICC Revenue($M) | C14: ='Raw Data'!F3 -> 3930 | D14: ='Raw Data'!G3 -> 2710 | E14: ='Raw Data'!H3 -> 3380 | F14: ='Raw Data'!I3 -> 2030 | G14: ='Raw Data'!J3 -> 4320 | H14: ='Raw Data'!K3 -> 3180 | I14: ='Raw Data'!L3 -> 2960 | J14: ='Raw Data'!M3 -> 2740
B15: Equities Rev($M) | C15: ='Raw Data'!F5 -> 3020 | D15: ='Raw Data'!G5 -> 2970 | E15: ='Raw Data'!H5 -> 2960 | F15: ='Raw Data'!I5 -> 2610 | G15: ='Raw Data'!J5 -> 3310 | H15: ='Raw Data'!K5 -> 3170 | I15: ='Raw Data'!L5 -> 3500 | J15: ='Raw Data'!M5 -> 3450 | M15: Base | N15: Bull | O15: Bear
B16: FICC YoY Growth | G16: =(G14-C14)/G14 -> 0.090277778 | H16: =(H14-D14)/H14 -> 0.14779874 | I16: =(I14-E14)/I14 -> -0.14189189 | J16: =(J14-F14)/J14 -> 0.25912409 | L16: FICC YoY Growth | M16: =AVERAGE(G16:J16) -> 0.088827179 | N16: 0.26 | O16: -0.14
B17: Equities YoY Growth | G17: =(G15-C15)/G15 -> 0.087613293 | H17: =(H15-D15)/H15 -> 0.063091483 | I17: =(I15-E15)/I15 -> 0.15428571 | J17: =(J15-F15)/J15 -> 0.24347826 | L17: Equities YoY Growth | M17: =AVERAGE(G17:J17) -> 0.13711719 | N17: 0.24 | O17: 0.06
B18: Headcount change | G18: =(G21-C21)/G21 -> -0.022522523 | H18: =(H21-D21)/H21 -> -0.006772009 | I18: =(I21-E21)/I21 -> 0.010775862 | J18: =(J21-F21)/J21 -> 0.025806452 | L18: Headcount change | M18: =AVERAGE(G18:J18) -> 0.0018219455 | N18: 0.03 | O18: -0.02
B19: Non-Comp Growth YoY | G19: =(G22-C22)/G22 -> 0.14747788 | H19: =(H22-D22)/H22 -> 0.12025184 | I19: =(I22-E22)/I22 -> 0.043256621 | J19: =(J22-F22)/J22 -> 0.097183491 | L19: Non-Comp Growth YoY | M19: =AVERAGE(G19:J19) -> 0.10204246 | N19: 0.04 | O19: 0.15
B20: Comp Ratio | C20: ='P&L Model'!F17 -> 0.3003777 | D20: ='P&L Model'!G17 -> 0.37372799 | E20: ='P&L Model'!H17 -> 0.3548265 | F20: ='P&L Model'!I17 -> 0.45452586 | G20: ='P&L Model'!J17 -> 0.31709987 | H20: ='P&L Model'!K17 -> 0.37544441 | I20: ='P&L Model'!L17 -> 0.35962601 | J20: ='P&L Model'!M17 -> 0.37287237 | L20: comp ratio | M20: =AVERAGE(C20:J20) -> 0.36356259 | N20: 0.3 | O20: 0.45
B21: Headcount | C21: ='Raw Data'!F13 -> 45400 | D21: ='Raw Data'!G13 -> 44600 | E21: ='Raw Data'!H13 -> 45900 | F21: ='Raw Data'!I13 -> 45300 | G21: ='Raw Data'!J13 -> 44400 | H21: ='Raw Data'!K13 -> 44300 | I21: ='Raw Data'!L13 -> 46400 | J21: ='Raw Data'!M13 -> 46500
B22: Non-Comp | C22: ='P&L Model'!F11 -> 2307.375 | D22: ='P&L Model'!G11 -> 2346.225 | E22: ='P&L Model'!H11 -> 2486.4 | F22: ='P&L Model'!I11 -> 2331 | G22: ='P&L Model'!J11 -> 2706.528 | H22: ='P&L Model'!K11 -> 2666.928 | I22: ='P&L Model'!L11 -> 2598.816 | J22: ='P&L Model'!M11 -> 2581.92

Sheet Assumptions Page 2
B2: MACRO ASSUMPTIONS | G2: BUSINESS ASSUMPTIONS
C4: Base | D4: Bull | E4: Bear | H4: Base | I4: Bull | J4: Bear
B5: VIX Quarterly Avg | C5: ='Assumptions Page 1'!M4 -> 15.76 | D5: ='Assumptions Page 1'!N4 -> 19.6 | E5: ='Assumptions Page 1'!O4 -> 13.59 | G5: FICC Revenue Growth (YoY) | H5: ='Assumptions Page 1'!M16 -> 0.088827179 | I5: ='Assumptions Page 1'!N16 -> 0.26 | J5: ='Assumptions Page 1'!O16 -> -0.14
B6: S&P 500 Return | C6: ='Assumptions Page 1'!M5 -> 0.0651875 | D6: ='Assumptions Page 1'!N5 -> 0.1373 | E6: ='Assumptions Page 1'!O5 -> 0.008 | G6: Equities Revenue Growth (YoY) | H6: ='Assumptions Page 1'!M17 -> 0.13711719 | I6: ='Assumptions Page 1'!N17 -> 0.24 | J6: ='Assumptions Page 1'!O17 -> 0.06
B7: Fed Funds Rate | C7: ='Assumptions Page 1'!M6 -> 0.050625 | D7: ='Assumptions Page 1'!N6 -> 0.0531 | E7: ='Assumptions Page 1'!O6 -> 0.0433 | G7: Headcount Change | H7: ='Assumptions Page 1'!M18 -> 0.0018219455 | I7: ='Assumptions Page 1'!N18 -> 0.03 | J7: ='Assumptions Page 1'!O18 -> -0.02
B8: 10Y Treasury Yield | C8: ='Assumptions Page 1'!M7 -> 0.0408875 | D8: ='Assumptions Page 1'!N7 -> 0.0459 | E8: ='Assumptions Page 1'!O7 -> 0.0348 | G8: Non-Comp Expense Growth | H8: ='Assumptions Page 1'!M19 -> 0.10204246 | I8: ='Assumptions Page 1'!N19 -> 0.04 | J8: ='Assumptions Page 1'!O19 -> 0.15
B9: Credit Spreads(bps) | C9: ='Assumptions Page 1'!M8 -> 108.875 | D9: ='Assumptions Page 1'!N8 -> 149 | E9: ='Assumptions Page 1'!O8 -> 82 | G9: Comp Ratio | H9: ='Assumptions Page 1'!M20 -> 0.36356259 | I9: ='Assumptions Page 1'!N20 -> 0.3 | J9: ='Assumptions Page 1'!O20 -> 0.45

Sheet Revenue Build
B2: FICC REVENUE BUILD
B4: FICC Revenue Build | C4: Base | D4: Bull | E4: Bear
B5: Prior Year FICC Revenue | C5: 13200 | D5: 13200 | E5: 13200
B6: × YoY Growth Rate (from Assump) | C6: ='Assumptions Page 2'!H5 -> 0.088827179 | D6: ='Assumptions Page 2'!I5 -> 0.26 | E6: ='Assumptions Page 2'!J5 -> -0.14
B7: Forecast FICC Revenue | C7: =C5+(C5*C6) -> 14372.519 | D7: =D5+(D5*D6) -> 16632 | E7: =E5+(E5*E6) -> 11352
B9: EQUITIES REVENUE BUILD
B11: Equities Revenue Build | C11: Base | D11: Bull | E11: Bear
B12: Prior Year Equities Revenue | C12: 13430 | D12: 13430 | E12: 13430
B13: × YoY Growth Rate (from Assump) | C13: ='Assumptions Page 1'!M17 -> 0.13711719 | D13: ='Assumptions Page 1'!N17 -> 0.24 | E13: ='Assumptions Page 1'!O17 -> 0.06
B14: Forecast Equities Revenue | C14: =C12+(C12*C13) -> 15271.484 | D14: =D12+(D12*D13) -> 16653.2 | E14: =E12+(E12*E13) -> 14235.8
B17: TOTAL REVENUE SUMMARY
B19: Equities Revenue Build | C19: Base | D19: Bull | E19: Bear
B20: FICC Revenue | C20: =C7 -> 14372.519 | D20: =D7 -> 16632 | E20: =E7 -> 11352
B21: Equities Revenue | C21: =C14 -> 15271.484 | D21: =D14 -> 16653.2 | E21: =E14 -> 14235.8
B22: Total Markets Revenue | C22: =C20+C21 -> 29644.003 | D22: =D20+D21 -> 33285.2 | E22: =E20+E21 -> 25587.8

Sheet Expense Build
B2: COMPENSATION
C3: Base | D3: Bull | E3: Bear
B4: Total Markets Revenue | C4: ='Revenue Build'!C22 -> 29644.003 | D4: ='Revenue Build'!D22 -> 33285.2 | E4: ='Revenue Build'!E22 -> 25587.8
B5: × Comp Ratio (from Assumptions) | C5: ='Assumptions Page 2'!H9 -> 0.36356259 | D5: ='Assumptions Page 2'!I9 -> 0.3 | E5: ='Assumptions Page 2'!J9 -> 0.45
B6: Compensation Expense | C6: =C4*C5 -> 10777.45 | D6: =D4*D5 -> 9985.56 | E6: =E4*E5 -> 11514.51
B8: NON - COMPENSATION
C9: Base | D9: Bull | E9: Bear
B10: Prior Year Non-Comp Expense | C10: 10544 | D10: 10544 | E10: 10544
B11: × Growth Rate (from Assumptions) | C11: ='Assumptions Page 2'!H8 -> 0.10204246 | D11: ='Assumptions Page 2'!I8 -> 0.04 | E11: ='Assumptions Page 2'!J8 -> 0.15
B12: Mon-Compensation Expense | C12: =C10+(C10*C11) -> 11619.936 | D12: =D10+(D10*D11) -> 10965.76 | E12: =E10+(E10*E11) -> 12125.6
B14: TOTAL EXPENSE AND MARGIN SUMMARY
C15: Base | D15: Bull | E15: Bear
B16: Total Revenue | C16: ='Revenue Build'!C22 -> 29644.003 | D16: ='Revenue Build'!D22 -> 33285.2 | E16: ='Revenue Build'!E22 -> 25587.8
B17: Total Compensation | C17: =C6 -> 10777.45 | D17: =D6 -> 9985.56 | E17: =E6 -> 11514.51
B18: Total Non-Compensation | C18: =C12 -> 11619.936 | D18: =D12 -> 10965.76 | E18: =E12 -> 12125.6
B19: Total Operating Expenses | C19: =C17+C18 -> 22397.386 | D19: =D17+D18 -> 20951.32 | E19: =E17+E18 -> 23640.11
B20: Pre Tax Income | C20: =C16-C19 -> 7246.6166 | D20: =D16-D19 -> 12333.88 | E20: =E16-E19 -> 1947.69
B21: Pre Tax Margin | C21: =C20/C16 -> 0.24445473 | D21: =D20/D16 -> 0.37055148 | E21: =E20/E16 -> 0.076117916

Sheet Scenario Output 
B2: FY 2025 Forecast Summary
B3: Metric | C3: Base | D3: Bull | E3: Bear
B4: FICC | C4: ='Revenue Build'!C7 -> 14372.519 | D4: ='Revenue Build'!D7 -> 16632 | E4: ='Revenue Build'!E7 -> 11352
B5: Equities | C5: ='Revenue Build'!C14 -> 15271.484 | D5: ='Revenue Build'!D14 -> 16653.2 | E5: ='Revenue Build'!E14 -> 14235.8
B6: Total Market Revenue | C6: ='Revenue Build'!C22 -> 29644.003 | D6: ='Revenue Build'!D22 -> 33285.2 | E6: ='Revenue Build'!E22 -> 25587.8
B8: Comp Exp | C8: ='Expense Build'!C6 -> 10777.45 | D8: ='Expense Build'!D6 -> 9985.56 | E8: ='Expense Build'!E6 -> 11514.51
B9: Non-Comp Exp | C9: ='Expense Build'!C12 -> 11619.936 | D9: ='Expense Build'!D12 -> 10965.76 | E9: ='Expense Build'!E12 -> 12125.6
B10: Total OpEx | C10: ='Expense Build'!C19 -> 22397.386 | D10: ='Expense Build'!D19 -> 20951.32 | E10: ='Expense Build'!E19 -> 23640.11
B12: Pre-Tax Income | C12: =C6-C10 -> 7246.6166 | D12: =D6-D10 -> 12333.88 | E12: =E6-E10 -> 1947.69
B13: Pre-Tax Margin | C13: =C12/C6 -> 0.24445473 | D13: =D12/D6 -> 0.37055148 | E13: =E12/E6 -> 0.076117916
B15: Key Macro Assumption:
B16: VIX | C16: ='Assumptions Page 2'!C5 -> 15.76 | D16: ='Assumptions Page 2'!D5 -> 19.6 | E16: ='Assumptions Page 2'!E5 -> 13.59
B17: S&P Return | C17: ='Assumptions Page 2'!C6 -> 0.0651875 | D17: ='Assumptions Page 2'!D6 -> 0.1373 | E17: ='Assumptions Page 2'!E6 -> 0.008

Sheet PBI Data
B4: Year | C4: Period | D4: Metric | E4: Value | F4: Scenario | H4: period | I4: metric | J4: value | K4: scenario
B5: 2023 | C5: Q1 | D5: FICC Revenue | E5: ='Raw Data'!F3 -> 3930 | F5: Actual | H5: FY 2022 | I5: Markets Revenue | J5: ='Raw Data'!B7+'Raw Data'!C7+'Raw Data'!D7+'Raw Data'!E7 -> 25310 | K5: Actual
B6: 2023 | C6: Q1 | D6: Equities Revenue | E6: ='Raw Data'!F5 -> 3020 | F6: Actual | H6: FY 2023 | I6: Markets Revenue | J6: ='Raw Data'!F7+'Raw Data'!G7+'Raw Data'!H7+'Raw Data'!I7 -> 23610 | K6: Actual
B7: 2023 | C7: Q1 | D7: Markets Revenue | E7: ='Raw Data'!F7 -> 6950 | F7: Actual | H7: FY 2024 | I7: Markets Revenue | J7: ='Raw Data'!J7+'Raw Data'!K7+'Raw Data'!L7+'Raw Data'!M7 -> 26630 | K7: Actual
B8: 2023 | C8: Q1 | D8: Compensation | E8: ='Raw Data'!F8 -> 2087.625 | F8: Actual | H8: FY 2024 | I8: Markets Revenue | J8: 26630 | K8: Bull
B9: 2023 | C9: Q1 | D9: Non-Compensation | E9: ='Raw Data'!F9 -> 2307.375 | F9: Actual | H9: FY 2024 | I9: Markets Revenue | J9: 26630 | K9: Base
B10: 2023 | C10: Q1 | D10: Total OpEx | E10: ='Raw Data'!F10 -> 4395 | F10: Actual | H10: FY 2025 | I10: Markets Revenue | J10: 26630 | K10: Bear
B11: 2023 | C11: Q1 | D11: Pre-Tax Income | E11: ='Raw Data'!F11 -> 3993 | F11: Actual | H11: FY 2025F | I11: Markets Revenue | J11: ='PBI Data'!E84 -> 33285.2 | K11: Bull
B12: 2023 | C12: Q1 | D12: Pre-Tax Margin % | E12: ='Raw Data'!F12 -> 0.32675941 | F12: Actual | H12: FY 2025F | I12: Markets Revenue | J12: ='PBI Data'!E83 -> 29644.003 | K12: Base
B13: 2023 | C13: Q1 | D13: Comp Ratio | E13: ='P&L Model'!F17 -> 0.3003777 | F13: Actual | H13: FY 2025F | I13: Markets Revenue | J13: ='PBI Data'!E85 -> 25587.8 | K13: Bear
B14: 2023 | C14: Q2 | D14: FICC Revenue | E14: ='Raw Data'!G3 -> 2710 | F14: Actual
B15: 2023 | C15: Q2 | D15: Equities Revenue | E15: ='Raw Data'!G5 -> 2970 | F15: Actual
B16: 2023 | C16: Q2 | D16: Markets Revenue | E16: ='Raw Data'!G7 -> 5680 | F16: Actual
B17: 2023 | C17: Q2 | D17: Compensation | E17: ='Raw Data'!G8 -> 2122.775 | F17: Actual
B18: 2023 | C18: Q2 | D18: Non-Compensation | E18: ='Raw Data'!G9 -> 2346.225 | F18: Actual
B19: 2023 | C19: Q2 | D19: Total OpEx | E19: ='Raw Data'!G10 -> 4469 | F19: Actual
B20: 2023 | C20: Q2 | D20: Pre-Tax Income | E20: ='Raw Data'!G11 -> 1736 | F20: Actual
B21: 2023 | C21: Q2 | D21: Pre-Tax Margin % | E21: ='Raw Data'!G12 -> 0.15926606 | F21: Actual
B22: 2023 | C22: Q2 | D22: Comp Ratio | E22: ='P&L Model'!G17 -> 0.37372799 | F22: Actual
B23: 2023 | C23: Q3 | D23: FICC Revenue | E23: ='Raw Data'!H3 -> 3380 | F23: Actual
B24: 2023 | C24: Q3 | D24: Equities Revenue | E24: ='Raw Data'!H5 -> 2960 | F24: Actual
B25: 2023 | C25: Q3 | D25: Markets Revenue | E25: ='Raw Data'!H7 -> 6340 | F25: Actual
B26: 2023 | C26: Q3 | D26: Compensation | E26: ='Raw Data'!H8 -> 2249.6 | F26: Actual
B27: 2023 | C27: Q3 | D27: Non-Compensation | E27: ='Raw Data'!H9 -> 2486.4 | F27: Actual
B28: 2023 | C28: Q3 | D28: Total OpEx | E28: ='Raw Data'!H10 -> 4736 | F28: Actual
B29: 2023 | C29: Q3 | D29: Pre-Tax Income | E29: ='Raw Data'!H11 -> 2756 | F29: Actual
B30: 2023 | C30: Q3 | D30: Pre-Tax Margin % | E30: ='Raw Data'!H12 -> 0.23316413 | F30: Actual
B31: 2023 | C31: Q3 | D31: Comp Ratio | E31: ='P&L Model'!H17 -> 0.3548265 | F31: Actual
B32: 2023 | C32: Q4 | D32: FICC Revenue | E32: ='Raw Data'!I3 -> 2030 | F32: Actual
B33: 2023 | C33: Q4 | D33: Equities Revenue | E33: ='Raw Data'!I5 -> 2610 | F33: Actual
B34: 2023 | C34: Q4 | D34: Markets Revenue | E34: ='Raw Data'!I7 -> 4640 | F34: Actual
B35: 2023 | C35: Q4 | D35: Compensation | E35: ='Raw Data'!I8 -> 2109 | F35: Actual
B36: 2023 | C36: Q4 | D36: Non-Compensation | E36: ='Raw Data'!I9 -> 2331 | F36: Actual
B37: 2023 | C37: Q4 | D37: Total OpEx | E37: ='Raw Data'!I10 -> 4440 | F37: Actual
B38: 2023 | C38: Q4 | D38: Pre-Tax Income | E38: ='Raw Data'!I11 -> 2254 | F38: Actual
B39: 2023 | C39: Q4 | D39: Pre-Tax Margin % | E39: ='Raw Data'!I12 -> 0.19911661 | F39: Actual
B40: 2023 | C40: Q4 | D40: Comp Ratio | E40: ='P&L Model'!I17 -> 0.45452586 | F40: Actual
B41: 2024 | C41: Q1 | D41: FICC Revenue | E41: ='Raw Data'!J3 -> 4320 | F41: Actual
B42: 2024 | C42: Q1 | D42: Equities Revenue | E42: ='Raw Data'!J5 -> 3310 | F42: Actual
B43: 2024 | C43: Q1 | D43: Markets Revenue | E43: ='Raw Data'!J7 -> 7630 | F43: Actual
...
